Workbook
Name _Toc301930468: TestDesign!#REF!
Name _Toc301930478: TestDesign!#REF!
Name ACTION: #REF!

Sheet Cover
B2: TEST CASE
B4: Project Name | C4: <Project Name> | F4: Creator
B5: Project Code | C5: <Project Code> | F5: Reviewer/Approver
B6: Document Code | C6: =C5&"_"&"XXX"&"_"&"vx.x" -> <Project Code>_XXX_vx.x | F6: Issue Date
F7: Version
B10: Record of change
B11: Effective Date | C11: Version | D11: Change Item | E11: *A,D,M | F11: Change description | G11: Reference
B12: <Date when these changes are effective> | G12: <List of documents which are referred in this version.>

Sheet Test case List
D1: TEST CASE LIST
B3: Project Name | D3: =Cover!C4 -> <Project Name>
B4: Project Code | D4: =Cover!C5 -> <Project Code>
B5: Test Environment Setup Description | D5: <List enviroment requires in this system 1. Server 2. Database 3. Web Browser ... >
B8: No | C8: Function Name | D8: Sheet Name | E8: Description | F8: Pre-Condition
B9: 2 | C9: Search & Basic Filters | D9: S02_SearchFilter!A1
B10: 11 | C10: Genre & Category Pages | D10: S11_GenreCategory

Sheet TestDesign
A1: Requirement Level 1 | B1: Requirement Level 2 | C1: Requirement Level 3 | D1: Test Criteria | E1: Test Type | F1: Note
A2: S02 Search & Filter | B2: Search | C2: Success | D2: Check search with valid keyword “Avengers Endgame” | E2: Function
D3: Check default value of controls in Logon screen | E3: GUI
D4: Check Max length of fields in Logon screen | E4: GUI
D5: Check login with right User name (Permission 1) & right Password | E5: Function
D6: Check login with right User name (Permission 2) & right Password | E6: Function
D7: Check login with right User name (Permission 3) & right Password | E7: Function
C8: Not success | D8: Check login with right User name & wrong Password | E8: Function
D9: Check login with wrong User name & right Password | E9: Function | F9: password of another user
D10: Check login with not exist User name | E10: Function
C11: Forgot password | D11: Click [Forgot Password] link - input right Username & right Email | E11: Function
D12: Click [Forgot Password] link - input right Username & wrong Email | E12: Function
D13: Click [Forgot Password] link - input wrong Username & right Email | E13: Function | F13: email of another user
D14: Click [Forgot Password] link - input not exist Username | E14: Function
C15: Not success | D15: Check search with non-exist keyword “XyzAbcNotExist12345” | E15: Function
C16: Success | D16: Check layout of Logon screen | E16: GUI
D17: Check default value of controls in Logon screen | E17: GUI
D18: Check Max length of fields in Logon screen | E18: GUI
D19: Check login with right User name (Permission 1) & right Password | E19: Function
D20: Check login with right User name (Permission 2) & right Password | E20: Function
D21: Check login with right User name (Permission 3) & right Password | E21: Function
C22: Not success | D22: Check login with right User name & wrong Password | E22: Function
D23: Check login with wrong User name & right Password | E23: Function | F23: password of another user
D24: Check login with not exist User name | E24: Function
C25: Forgot password | D25: Click [Forgot Password] link - input right Username & right Email | E25: Function
D26: Click [Forgot Password] link - input right Username & wrong Email | E26: Function
D27: Click [Forgot Password] link - input wrong Username & right Email | E27: Function | F27: email of another user
D28: Click [Forgot Password] link - input not exist Username | E28: Function
D29: Click [Log out] link | E29: Function
C30: Special character | D30: Check search with special characters “@#$%^&*()” hoặc malicious script | E30: Function / Security
B31: Filter | C31: Genre | D31: Check filter movies by Genre = “Action” | E31: Function
C32: Year | D32: Check filter movies by Year = “2023” | E32: Function
B33: Search + Filter | C33: Multiple filters | D33: Check search “Spider” + Genre: Action + Year: 2022 | E33: Function
B34: Filter | C34: Reset filters | D34: Click “Clear Filters / Reset” → all filters return to default | E34: Function
A35: S11 Genre & Category | B35: Genre Page | C35: Action | D35: Navigate to /genre/action | E35: Function
C36: Horror | D36: Navigate to /genre/horror
C37: Filter by Year | D37: Check Action movies filtered by Year = 2023
C38: Filter by Country | D38: Check movies filtered by Country = “South Korea”
B39: Category | C39: Top Rated | D39: Navigate to /top-rated
C40: Recently Added | D40: Navigate to /recently-added
...

Sheet S02_SearchFilter
A2: Module Code | B2: S02_SearchFilter | I2: Passed
A3: Test requirement | B3: <Brief description about requirements which are tested in this sheet> | I3: Failed
A4: Tester | I4: Blocked
A5: Passed | B5: Failed | C5: Untested | D5: Blocked | E5: Skipped | F5: Number of Test cases | I5: Untested
A6: =COUNTIF(F9:F991,"Passed") -> 7 | B6: =COUNTIF(F9:F991,"Failed") -> 0 | C6: =F6-E6-D6-B6-A6 -> 0 | D6: =COUNTIF(F$9:F$991,"Blocked") -> 0 | E6: =COUNTIF(F$9:F$991,"Skipped") -> 0 | F6: =COUNTA(A9:A991) -> 7 | I6: Skipped
A8: ID | B8: Test Case Description | C8: Test Case Procedure | D8: Expected Output | E8: Inter-test case Dependence | F8: Result | G8: Test date | H8: Note
A9: =IF(OR(B9<>"",D9<>""),"["&TEXT($B$2,"##")&"-"&TEXT(ROW()-10,"##")&"]","") -> [S02_SearchFilter--1] | B9: Tìm kiếm với từ khóa hợp lệ "Avengers Endgame". | C9: Mở trang Movies/Search. Nhập “Avengers Endgame” vào search box. Nhấn Enter hoặc click Search button. | D9: Danh sách phim hiển thị chứa “Avengers Endgame”. Số lượng kết quả > 0. Mỗi movie card hiển thị đúng tên, năm, poster. URL có dạng: ?search=avengers+endgame. | E9: <List all test cases or conditions that must be done before performing this case> | F9: Passed
A10: =IF(OR(B10<>"",D10<>""),"["&TEXT($B$2,"##")&"-"&TEXT(ROW()-12,"##")&"]","") -> [S02_SearchFilter--2] | B10: Tìm kiếm với từ khóa không tồn tại. | C10: Nhập “XyzAbcNotExist12345”. Nhấn Search. | D10: Hiển thị “No results found”. Không có movie card nào. Gợi ý đổi từ khóa. | E10: S02-01 (đảm bảo chức năng Search hoạt động) | F10: Passed
A11: =IF(OR(B11<>"",D11<>""),"["&TEXT($B$2,"##")&"-"&TEXT(ROW()-14,"##")&"]","") -> [S02_SearchFilter--3] | B11: Tìm kiếm với ký tự đặc biệt hoặc chuỗi SQL Injection. | C11: Nhập "@#$%^&*()" hoặc "'; DROP TABLE movies; --". Nhấn Search. | D11: Không crash. Input được sanitize. Không thực thi mã độc. Hiển thị “No results”. | E11: S02-01 (kiểm tra baseline search) | F11: Passed
A12: =IF(OR(B12<>"",D12<>""),"["&TEXT($B$2,"##")&"-"&TEXT(ROW()-16,"##")&"]","") -> [S02_SearchFilter--4] | B12: Lọc phim theo Genre = Action. | C12: Chọn Genre = Action. | D12: Chỉ hiển thị phim Action. Filter UI hiển thị Action active. URL chứa ?genre=action. | F12: Passed
A13: =IF(OR(B13<>"",D13<>""),"["&TEXT($B$2,"##")&"-"&TEXT(ROW()-18,"##")&"]","") -> [S02_SearchFilter--5] | B13: Lọc phim theo năm 2023. | C13: Chọn Year = 2023. Click Filter. | D13: Chỉ hiển thị phim năm 2023. Mỗi card có year = 2023. | F13: Passed
A14: =IF(OR(B12<>"",D12<>""),"["&TEXT($B$2,"##")&"-"&TEXT(ROW()-20,"##")&"]","") -> [S02_SearchFilter--6] | B14: Search “Spider” + Genre Action + Year 2022. | C14: Nhập search = “Spider”. Select Genre = Action. Select Year = 2022. Apply filter. | D14: Kết quả phải match cả 3 điều kiện. URL = ?search=spider&genre=action&year=2022. Nếu không có kết quả → “No matches”. | E14: S02-01 (Search) S02-04 (Filter Genre) S02-05 (Filter Year) | F14: Passed
A15: =IF(OR(B12<>"",D12<>""),"["&TEXT($B$2,"##")&"-"&TEXT(ROW()-22,"##")&"]","") -> [S02_SearchFilter--7] | B15: Reset toàn bộ filter. | C15: Bật nhiều filters. Click “Clear Filters” hoặc “Reset”. | D15: Tất cả filter về default. Hiển thị toàn bộ phim. URL trở về /movies hoặc /search. | E15: S02-04 hoặc S02-05 hoặc S02-06 | F15: Passed

Sheet S11_GenreCategory
A2: Module Code | B2: S11_GenreCategory | I2: Passed
A3: Test requirement | B3: <Brief description about requirements which are tested in this sheet> | I3: Failed
A4: Tester | I4: Blocked
A5: Passed | B5: Failed | C5: Untested | D5: Blocked | E5: Skipped | F5: Number of Test cases | I5: Untested
A6: =COUNTIF(F9:F991,"Passed") -> 7 | B6: =COUNTIF(F9:F991,"Failed") -> 0 | C6: =F6-E6-D6-B6-A6 -> 0 | D6: =COUNTIF(F$9:F$991,"Blocked") -> 0 | E6: =COUNTIF(F$9:F$991,"Skipped") -> 0 | F6: =COUNTA(A9:A991) -> 7 | I6: Skipped
A8: ID | B8: Test Case Description | C8: Test Case Procedure | D8: Expected Output | E8: Inter-test case Dependence | F8: Result | G8: Test date | H8: Note
A9: =IF(OR(B9<>"",D9<>""),"["&TEXT($B$2,"##")&"-"&TEXT(ROW()-10,"##")&"]","") -> [S11_GenreCategory--1] | B9: Truy cập trang thể loại Action. | C9: Navigate đến URL: /genre/action. | D9: Page title hiển thị: "Action Movies". Chỉ phim có genre “Action” được hiển thị. Mỗi movie card có tag Action. | E9: <List all test cases or conditions that must be done before performing this case> | F9: Passed
A10: =IF(OR(B10<>"",D10<>""),"["&TEXT($B$2,"##")&"-"&TEXT(ROW()-12,"##")&"]","") -> [S11_GenreCategory--2] | B10: Truy cập trang thể loại Horror. | C10: Navigate đến URL: /genre/horror. | D10: Title: "Horror Movies". Chỉ hiển thị phim Horror. Giao diện theme tối hoạt động đúng. | E10: S11-01 (baseline Genre page behavior) | F10: Passed
A11: =IF(OR(B11<>"",D11<>""),"["&TEXT($B$2,"##")&"-"&TEXT(ROW()-14,"##")&"]","") -> [S11_GenreCategory--3] | B11: Filter Year trong trang /genre/action. | C11: Mở /genre/action. Chọn Year = 2023. Click Apply. | D11: Kết quả là các phim Action của năm 2023. URL: /genre/action?year=2023. | E11: S11-01 (Genre Action loaded) | F11: Passed
A12: =IF(OR(B12<>"",D12<>""),"["&TEXT($B$2,"##")&"-"&TEXT(ROW()-16,"##")&"]","") -> [S11_GenreCategory--4] | B12: Lọc theo quốc gia “South Korea”. | C12: Trên trang Genre (Action), chọn Country = South Korea. Click Apply. | D12: Chỉ hiển thị Action movies của Hàn Quốc. Movie cards có flag icon 🇰🇷. | E12: S11-01 (Genre Action) S11-03 (Filter structure) | F12: Passed
A13: =IF(OR(B13<>"",D13<>""),"["&TEXT($B$2,"##")&"-"&TEXT(ROW()-18,"##")&"]","") -> [S11_GenreCategory--5] | B13: Kiểm tra trang Top Rated. | C13: Navigate đến /top-rated. | D13: Phim được sắp xếp từ rating cao → thấp. Mỗi card có badge “⭐ Top Rated”. | F13: Passed
A14: =IF(OR(B12<>"",D12<>""),"["&TEXT($B$2,"##")&"-"&TEXT(ROW()-20,"##")&"]","") -> [S11_GenreCategory--6] | B14: Kiểm tra trang Recently Added. | C14: Navigate đến /recently-added. | D14: Phim mới được thêm hiển thị đầu tiên theo thứ tự thời gian. Badge “NEW” hiển thị trên movie card. | F14: Passed
A15: =IF(OR(B12<>"",D12<>""),"["&TEXT($B$2,"##")&"-"&TEXT(ROW()-22,"##")&"]","") -> [S11_GenreCategory--7] | B15: Thử filter trả về 0 kết quả. | C15: Apply Genre = Documentary. Apply Year = 1920. | D15: Hiển thị thông báo: “No movies found”. Suggestion link: “Browse all movies”. | E15: S11-01 hoặc S11-02 (load genre page), Filter logic từ S11-03. | F15: Passed

Sheet Test Report
B1: TEST REPORT
B3: Project Name | C3: <Project Name> | E3: Creator
B4: Project Code | C4: <Project Code> | E4: Reviewer/Approver
B5: Document Code | C5: =C4&"_"&"Test Report"&"_"&"vx.x" -> <Project Code>_Test Report_vx.x | E5: Issue Date | H5: <Date when this test report is created>
B6: Notes | C6: <List modules included in this release> ex: Release 1 includes 2 modules: Module1 and Module2
B9: No | C9: Module code | D9: Pass | E9: Fail | F9: Untested | G9: Blocked | H9: Skipped | I9: Number of test cases
B10: 1 | C10: =S02_SearchFilter!B2 -> S02_SearchFilter | D10: =S02_SearchFilter!A6 -> 7 | E10: =S02_SearchFilter!B6 -> 0 | F10: =S02_SearchFilter!C6 -> 0 | G10: =S02_SearchFilter!D6 -> 0 | H10: =S02_SearchFilter!E6 -> 0 | I10: =S02_SearchFilter!F6 -> 7
B11: 2 | C11: =S11_GenreCategory!B2 -> S11_GenreCategory | D11: =S11_GenreCategory!A6 -> 7 | E11: =S11_GenreCategory!B6 -> 0 | F11: =S11_GenreCategory!C6 -> 0 | G11: =S11_GenreCategory!D6 -> 0 | H11: =S11_GenreCategory!E6 -> 0 | I11: =S11_GenreCategory!F6 -> 7
C13: Sub total | D13: =SUM(D8:D12) -> 14 | E13: =SUM(E8:E12) -> 0 | F13: =SUM(F8:F12) -> 0 | G13: =SUM(G8:G12) -> 0 | H13: =SUM(H8:H12) -> 0 | I13: =SUM(I8:I12) -> 14
C15: Test coverage | E15: =(D13+E13)*100/(I13-H13-G13) -> 100 | F15: %
C16: Test successful coverage | E16: =D13*100/(D13+E13) -> 100 | F16: %
